<?xml version='1.0'?>
<sdf version='1.6'>
  <world name='default'>
    <light name='sun' type='directional'>
      <cast_shadows>1</cast_shadows>
      <pose frame=''>0 0 10 0 -0 0</pose>
      <diffuse>0.8 0.8 0.8 1</diffuse>
      <specular>0.2 0.2 0.2 1</specular>
      <attenuation>
        <range>1000</range>
        <constant>0.9</constant>
        <linear>0.01</linear>
        <quadratic>0.001</quadratic>
      </attenuation>
      <direction>-0.5 0.1 -0.9</direction>
    </light>
    <model name='ground_plane'>
      <static>1</static>
      <link name='link'>
        <collision name='collision'>
          <geometry>
            <plane>
              <normal>0 0 1</normal>
              <size>100 100</size>
            </plane>
          </geometry>
          <surface>
            <friction>
              <ode>
                <mu>100</mu>
                <mu2>50</mu2>
              </ode>
            </friction>
          </surface>
        </collision>
        <visual name='visual'>
          <cast_shadows>0</cast_shadows>
          <geometry>
            <plane>
              <normal>0 0 1</normal>
              <size>100 100</size>
            </plane>
          </geometry>
          <material>
            <script>
              <uri>file://media/materials/scripts/gazebo.material</uri>
              <name>Gazebo/Grey</name>
            </script>
          </material>
        </visual>
      </link>
    </model>
    <plugin name='distributor' filename='libdistributorPlugin.so'>
      <rofi>
        <id>2</id>
        <name>rofi_2</name>
      </rofi>
      <rofi>
        <id>1</id>
        <name>rofi_1</name>
      </rofi>
    </plugin>
    <plugin name='attacher' filename='libattacherPlugin.so'>
      <connection>
        <orientation>2</orientation>
        <roficom>rofi_1::connectorAminusZ</roficom>
        <roficom>rofi_2::connectorAminusZ</roficom>
      </connection>
    </plugin>
    <gravity>0 0 -9.8</gravity>
    <magnetic_field>6e-06 2.3e-05 -4.2e-05</magnetic_field>
    <atmosphere type='adiabatic'/>
    <physics name='default_physics' default='0' type='ode'>
      <max_step_size>0.001</max_step_size>
      <real_time_factor>1</real_time_factor>
      <real_time_update_rate>1000</real_time_update_rate>
    </physics>
    <scene>
      <ambient>0.4 0.4 0.4 1</ambient>
      <background>0.7 0.7 0.7 1</background>
      <shadows>1</shadows>
    </scene>
    <state world_name='default'>
      <model name='rofi_2'>
        <pose>-0 0.15 0.0425 0 -1.5708 0</pose>
        <link name='bodyA'>
          <pose>-0 0.15 0.0425 0 -1.5708 0</pose>
        </link>
        <link name='bodyB'>
          <pose>-0 0.15 0.0425 0 -1.5708 0</pose>
        </link>
        <link name='shoeA'>
          <pose>-0 0.1 0.016 0 -1.5708 0</pose>
        </link>
        <link name='shoeB'>
          <pose>-0.0015 0.2 0.016 0 -1.5708 0</pose>
        </link>
        <model name='connectorAplusX'>
          <pose>-0 0.1 0.0855 -4e-06 4e-06 -1.5708</pose>
          <link name='RoFICoM::inner'>
            <pose>-0 0.1 0.0855 -4e-06 4e-06 -1.5708</pose>
          </link>
        </model>
        <model name='connectorAminusX'>
          <pose>-0 0.1 -0.0005 3.14159 4e-06 1.5708</pose>
          <link name='RoFICoM::inner'>
            <pose>-0 0.1 -0.0005 3.14159 4e-06 1.5708</pose>
          </link>
        </model>
        <model name='connectorAminusZ'>
          <pose>-0 0.057 0.0425 1.5708 -1.5708 0</pose>
          <link name='RoFICoM::inner'>
            <pose>0 0.05 0.0425 1.5708 -1.5708 0</pose>
          </link>
        </model>
        <model name='connectorBplusX'>
          <pose>-0 0.2 -0.0005 3.14159 4e-06 1.5708</pose>
          <link name='RoFICoM::inner'>
            <pose>-0 0.2 -0.0005 3.14159 4e-06 1.5708</pose>
          </link>
        </model>
        <model name='connectorBminusX'>
          <pose>-0 0.2 0.0855 -4e-06 4e-06 -1.5708</pose>
          <link name='RoFICoM::inner'>
            <pose>-0 0.2 0.0855 -4e-06 4e-06 -1.5708</pose>
          </link>
        </model>
        <model name='connectorBminusZ'>
          <pose>-0 0.243 0.0425 -3.14159 1.57079 -1.5708</pose>
          <link name='RoFICoM::inner'>
            <pose>-0 0.243 0.0425 -3.14159 1.57079 -1.5708</pose>
          </link>
        </model>
      </model>
      <model name='rofi_1'>
        <pose>0 -0.05 0.0425 3.14159 1.5708 0</pose>
        <link name='bodyA'>
          <pose>0 -0.05 0.0425 3.14159 1.5708 0</pose>
        </link>
        <link name='bodyB'>
          <pose>0 -0.05 0.0425 -3.14159 1.5708 0</pose>
        </link>
        <link name='shoeA'>
          <pose>-0 0 0.069 3.14159 1.5708 0</pose>
        </link>
        <link name='shoeB'>
          <pose>-0.0015 -0.1 0.069 -3.14159 1.5708 0</pose>
        </link>
        <model name='connectorAplusX'>
          <pose>0 0 -0.0005 3.14159 -4e-06 1.5708</pose>
          <link name='RoFICoM::inner'>
            <pose>0 0 -0.0005 3.14159 -4e-06 1.5708</pose>
          </link>
        </model>
        <model name='connectorAminusX'>
          <pose>-0 0 0.0855 -4e-06 -4e-06 -1.5708</pose>
          <link name='RoFICoM::inner'>
            <pose>-0 0 0.0855 -4e-06 -4e-06 -1.5708</pose>
          </link>
        </model>
        <model name='connectorAminusZ'>
          <pose>-0 0.043 0.0425 -1.57079 1.5708 0</pose>
          <link name='RoFICoM::inner'>
            <pose>0 0.05 0.0425 -1.57079 1.5708 0</pose>
          </link>
        </model>
        <model name='connectorBplusX'>
          <pose>0 -0.1 0.0855 -4e-06 -4e-06 -1.5708</pose>
          <link name='RoFICoM::inner'>
            <pose>0 -0.1 0.0855 -4e-06 -4e-06 -1.5708</pose>
          </link>
        </model>
        <model name='connectorBminusX'>
          <pose>0 -0.1 -0.0005 3.14159 -4e-06 1.5708</pose>
          <link name='RoFICoM::inner'>
            <pose>0 -0.1 -0.0005 3.14159 -4e-06 1.5708</pose>
          </link>
        </model>
        <model name='connectorBminusZ'>
          <pose>0 -0.143 0.0425 4e-06 -1.57079 1.5708</pose>
          <link name='RoFICoM::inner'>
            <pose>0 -0.143 0.0425 4e-06 -1.57079 1.5708</pose>
          </link>
        </model>
      </model>
    </state>
    <model name='rofi_2'>
      <link name='bodyA'>
        <self_collide>1</self_collide>
        <inertial>
          <pose frame=''>0 -0.029663 0 0 -0 0</pose>
          <mass>0.201058</mass>
          <inertia>
            <ixx>0.00016</ixx>
            <ixy>0</ixy>
            <ixz>0</ixz>
            <iyy>0.00013</iyy>
            <iyz>0</iyz>
            <izz>0.000158</izz>
          </inertia>
        </inertial>
        <visual name='visual-bodyA'>
          <pose frame=''>0 0 0 0 -0 0</pose>
          <geometry>
            <mesh>
              <uri>model://universalModule/meshes/model.obj</uri>
              <scale>0.001 0.001 0.001</scale>
              <submesh>
                <name>bodyA</name>
              </submesh>
            </mesh>
          </geometry>
          <material>
            <lighting>1</lighting>
            <script>
              <uri>file://media/materials/scripts/gazebo.material</uri>
              <name>Gazebo/DarkGrey</name>
            </script>
            <shader type='pixel'>
              <normal_map>__default__</normal_map>
            </shader>
          </material>
        </visual>
        <collision name='collision-bodyA'>
          <pose frame=''>0 0 0 0 -0 0</pose>
          <geometry>
            <mesh>
              <uri>model://universalModule/meshes/model.obj</uri>
              <scale>0.001 0.001 0.001</scale>
              <submesh>
                <name>bodyA</name>
              </submesh>
            </mesh>
          </geometry>
        </collision>
      </link>
      <link name='bodyB'>
        <self_collide>1</self_collide>
        <inertial>
          <pose frame=''>0 0.029663 0 0 -0 0</pose>
          <mass>0.201058</mass>
          <inertia>
            <ixx>0.00016</ixx>
            <ixy>0</ixy>
            <ixz>0</ixz>
            <iyy>0.00013</iyy>
            <iyz>0</iyz>
            <izz>0.000158</izz>
          </inertia>
        </inertial>
        <visual name='visual-bodyB'>
          <pose frame=''>0 0 0 0 -0 0</pose>
          <geometry>
            <mesh>
              <uri>model://universalModule/meshes/model.obj</uri>
              <scale>0.001 0.001 0.001</scale>
              <submesh>
                <name>bodyB</name>
              </submesh>
            </mesh>
          </geometry>
          <material>
            <lighting>1</lighting>
            <script>
              <uri>file://media/materials/scripts/gazebo.material</uri>
              <name>Gazebo/DarkGrey</name>
            </script>
            <shader type='pixel'>
              <normal_map>__default__</normal_map>
            </shader>
          </material>
        </visual>
        <collision name='collision-bodyB'>
          <pose frame=''>0 0 0 0 -0 0</pose>
          <geometry>
            <mesh>
              <uri>model://universalModule/meshes/model.obj</uri>
              <scale>0.001 0.001 0.001</scale>
              <submesh>
                <name>bodyB</name>
              </submesh>
            </mesh>
          </geometry>
        </collision>
      </link>
      <link name='shoeA'>
        <self_collide>0</self_collide>
        <pose frame=''>-0.0265 -0.05 0 0 -0 0</pose>
        <inertial>
          <pose frame=''>0.0265 -0.012973 0 0 -0 0</pose>
          <mass>0.089474</mass>
          <inertia>
            <ixx>5.9e-05</ixx>
            <ixy>0</ixy>
            <ixz>0</ixz>
            <iyy>0.000103</iyy>
            <iyz>0</iyz>
            <izz>0.000117</izz>
          </inertia>
        </inertial>
        <collision name='shoeA-collision'>
          <pose frame=''>0.0265 0.05 -0 0 -0 0</pose>
          <geometry>
            <mesh>
              <uri>model://universalModule/meshes/model.obj</uri>
              <scale>0.001 0.001 0.001</scale>
              <submesh>
                <name>shoeA</name>
              </submesh>
            </mesh>
          </geometry>
        </collision>
        <visual name='shoeA-visual'>
          <pose frame=''>0.0265 0.05 -0 0 -0 0</pose>
          <geometry>
            <mesh>
              <uri>model://universalModule/meshes/model.obj</uri>
              <scale>0.001 0.001 0.001</scale>
              <submesh>
                <name>shoeA</name>
              </submesh>
            </mesh>
          </geometry>
          <material>
            <lighting>1</lighting>
            <script>
              <uri>file://media/materials/scripts/gazebo.material</uri>
              <name>Gazebo/Yellow</name>
            </script>
            <shader type='pixel'>
              <normal_map>__default__</normal_map>
            </shader>
          </material>
        </visual>
      </link>
      <link name='shoeB'>
        <self_collide>0</self_collide>
        <pose frame=''>-0.0265 0.05 0.0015 0 -0 0</pose>
        <inertial>
          <pose frame=''>0.0265 0.012973 0 0 -0 0</pose>
          <mass>0.089474</mass>
          <inertia>
            <ixx>5.9e-05</ixx>
            <ixy>0</ixy>
            <ixz>0</ixz>
            <iyy>0.000103</iyy>
            <iyz>0</iyz>
            <izz>0.000117</izz>
          </inertia>
        </inertial>
        <collision name='shoeB-collision'>
          <pose frame=''>0.0265 -0.05 -0.0015 0 -0 0</pose>
          <geometry>
            <mesh>
              <uri>model://universalModule/meshes/model.obj</uri>
              <scale>0.001 0.001 0.001</scale>
              <submesh>
                <name>shoeB</name>
              </submesh>
            </mesh>
          </geometry>
        </collision>
        <visual name='shoeB-visual'>
          <pose frame=''>0.0265 -0.05 -0.0015 0 -0 0</pose>
          <geometry>
            <mesh>
              <uri>model://universalModule/meshes/model.obj</uri>
              <scale>0.001 0.001 0.001</scale>
              <submesh>
                <name>shoeB</name>
              </submesh>
            </mesh>
          </geometry>
          <material>
            <lighting>1</lighting>
            <script>
              <uri>file://media/materials/scripts/gazebo.material</uri>
              <name>Gazebo/Yellow</name>
            </script>
            <shader type='pixel'>
              <normal_map>__default__</normal_map>
            </shader>
          </material>
        </visual>
      </link>
      <model name='connectorAplusX'>
        <pose frame=''>0.043 -0.05 0 -1.5708 -0 -1.5708</pose>
        <self_collide>0</self_collide>
        <link name='RoFICoM::outer'>
          <inertial>
            <pose frame=''>0 0 -0.0085 0 -0 0</pose>
            <mass>0.01</mass>
            <inertia>
              <ixx>1.77583e-06</ixx>
              <iyy>1.77583e-06</iyy>
              <izz>3.125e-06</izz>
              <ixy>0</ixy>
              <ixz>0</ixz>
              <iyz>0</iyz>
            </inertia>
          </inertial>
          <collision name='outer-collision'>
            <pose frame=''>0 0 -0.0085 0 -0 0</pose>
            <geometry>
              <cylinder>
                <radius>0.025</radius>
                <length>0.017</length>
              </cylinder>
            </geometry>
          </collision>
          <visual name='visual'>
            <pose frame=''>0 0 -0.0085 0 -0 0</pose>
            <geometry>
              <cylinder>
                <radius>0.025</radius>
                <length>0.017</length>
              </cylinder>
            </geometry>
            <material>
              <script>
                <uri>file://media/materials/scripts/gazebo.material</uri>
                <name>Gazebo/DarkGrey</name>
              </script>
            </material>
          </visual>
          <pose frame=''>0 0 0 0 -0 0</pose>
        </link>
        <link name='RoFICoM::inner'>
          <inertial>
            <pose frame=''>0 0 -0.0035 0 -0 0</pose>
            <mass>0.01</mass>
            <inertia>
              <ixx>1.3633e-06</ixx>
              <iyy>1.3633e-06</iyy>
              <izz>2.645e-06</izz>
              <ixy>0</ixy>
              <ixz>0</ixz>
              <iyz>0</iyz>
            </inertia>
          </inertial>
          <collision name='inner-collision'>
            <pose frame=''>0 0 -0.0035 0 -0 0</pose>
            <geometry>
              <cylinder>
                <radius>0.023</radius>
                <length>0.007</length>
              </cylinder>
            </geometry>
          </collision>
          <visual name='visual'>
            <pose frame=''>0 0 -0.0035 0 -0 0</pose>
            <geometry>
              <cylinder>
                <radius>0.023</radius>
                <length>0.007</length>
              </cylinder>
            </geometry>
            <material>
              <script>
                <uri>file://media/materials/scripts/gazebo.material</uri>
                <name>Gazebo/DarkGrey</name>
              </script>
            </material>
          </visual>
          <pose frame=''>0 0 0 0 -0 0</pose>
        </link>
        <joint name='RoFICoM::extendJoint' type='prismatic'>
          <parent>RoFICoM::outer</parent>
          <child>RoFICoM::inner</child>
          <axis>
            <xyz>0 0 1</xyz>
            <limit>
              <lower>0</lower>
              <upper>0.007</upper>
              <effort>50</effort>
              <velocity>0.025</velocity>
            </limit>
            <initial_position>0</initial_position>
            <dynamics>
              <friction>0</friction>
              <spring_reference>0</spring_reference>
              <spring_stiffness>0</spring_stiffness>
            </dynamics>
            <use_parent_model_frame>1</use_parent_model_frame>
          </axis>
        </joint>
        <plugin name='roficom' filename='libroficomPlugin.so'>
          <joint>RoFICoM::extendJoint</joint>
          <extend>0</extend>
        </plugin>
      </model>
      <model name='connectorAminusX'>
        <pose frame=''>-0.043 -0.05 0 -1.5708 0 1.5708</pose>
        <self_collide>0</self_collide>
        <link name='RoFICoM::outer'>
          <inertial>
            <pose frame=''>0 0 -0.0085 0 -0 0</pose>
            <mass>0.01</mass>
            <inertia>
              <ixx>1.77583e-06</ixx>
              <iyy>1.77583e-06</iyy>
              <izz>3.125e-06</izz>
              <ixy>0</ixy>
              <ixz>0</ixz>
              <iyz>0</iyz>
            </inertia>
          </inertial>
          <collision name='outer-collision'>
            <pose frame=''>0 0 -0.0085 0 -0 0</pose>
            <geometry>
              <cylinder>
                <radius>0.025</radius>
                <length>0.017</length>
              </cylinder>
            </geometry>
          </collision>
          <visual name='visual'>
            <pose frame=''>0 0 -0.0085 0 -0 0</pose>
            <geometry>
              <cylinder>
                <radius>0.025</radius>
                <length>0.017</length>
              </cylinder>
            </geometry>
            <material>
              <script>
                <uri>file://media/materials/scripts/gazebo.material</uri>
                <name>Gazebo/DarkGrey</name>
              </script>
            </material>
          </visual>
          <pose frame=''>0 0 0 0 -0 0</pose>
        </link>
        <link name='RoFICoM::inner'>
          <inertial>
            <pose frame=''>0 0 -0.0035 0 -0 0</pose>
            <mass>0.01</mass>
            <inertia>
              <ixx>1.3633e-06</ixx>
              <iyy>1.3633e-06</iyy>
              <izz>2.645e-06</izz>
              <ixy>0</ixy>
              <ixz>0</ixz>
              <iyz>0</iyz>
            </inertia>
          </inertial>
          <collision name='inner-collision'>
            <pose frame=''>0 0 -0.0035 0 -0 0</pose>
            <geometry>
              <cylinder>
                <radius>0.023</radius>
                <length>0.007</length>
              </cylinder>
            </geometry>
          </collision>
          <visual name='visual'>
            <pose frame=''>0 0 -0.0035 0 -0 0</pose>
            <geometry>
              <cylinder>
                <radius>0.023</radius>
                <length>0.007</length>
              </cylinder>
            </geometry>
            <material>
              <script>
                <uri>file://media/materials/scripts/gazebo.material</uri>
                <name>Gazebo/DarkGrey</name>
              </script>
            </material>
          </visual>
          <pose frame=''>0 0 0 0 -0 0</pose>
        </link>
        <joint name='RoFICoM::extendJoint' type='prismatic'>
          <parent>RoFICoM::outer</parent>
          <child>RoFICoM::inner</child>
          <axis>
            <xyz>0 0 1</xyz>
            <limit>
              <lower>0</lower>
              <upper>0.007</upper>
              <effort>50</effort>
              <velocity>0.025</velocity>
            </limit>
            <initial_position>0</initial_position>
            <dynamics>
              <friction>0</friction>
              <spring_reference>0</spring_reference>
              <spring_stiffness>0</spring_stiffness>
            </dynamics>
            <use_parent_model_frame>1</use_parent_model_frame>
          </axis>
        </joint>
        <plugin name='roficom' filename='libroficomPlugin.so'>
          <joint>RoFICoM::extendJoint</joint>
          <extend>0</extend>
        </plugin>
      </model>
      <model name='connectorAminusZ'>
        <pose frame=''>0 -0.093 0 1.5708 -0 0</pose>
        <self_collide>0</self_collide>
        <link name='RoFICoM::outer'>
          <inertial>
            <pose frame=''>0 0 -0.0085 0 -0 0</pose>
            <mass>0.01</mass>
            <inertia>
              <ixx>1.77583e-06</ixx>
              <iyy>1.77583e-06</iyy>
              <izz>3.125e-06</izz>
              <ixy>0</ixy>
              <ixz>0</ixz>
              <iyz>0</iyz>
            </inertia>
          </inertial>
          <collision name='outer-collision'>
            <pose frame=''>0 0 -0.0085 0 -0 0</pose>
            <geometry>
              <cylinder>
                <radius>0.025</radius>
                <length>0.017</length>
              </cylinder>
            </geometry>
          </collision>
          <visual name='visual'>
            <pose frame=''>0 0 -0.0085 0 -0 0</pose>
            <geometry>
              <cylinder>
                <radius>0.025</radius>
                <length>0.017</length>
              </cylinder>
            </geometry>
            <material>
              <script>
                <uri>file://media/materials/scripts/gazebo.material</uri>
                <name>Gazebo/DarkGrey</name>
              </script>
            </material>
          </visual>
          <pose frame=''>0 0 0 0 -0 0</pose>
        </link>
        <link name='RoFICoM::inner'>
          <inertial>
            <pose frame=''>0 0 -0.0035 0 -0 0</pose>
            <mass>0.01</mass>
            <inertia>
              <ixx>1.3633e-06</ixx>
              <iyy>1.3633e-06</iyy>
              <izz>2.645e-06</izz>
              <ixy>0</ixy>
              <ixz>0</ixz>
              <iyz>0</iyz>
            </inertia>
          </inertial>
          <collision name='inner-collision'>
            <pose frame=''>0 0 -0.0035 0 -0 0</pose>
            <geometry>
              <cylinder>
                <radius>0.023</radius>
                <length>0.007</length>
              </cylinder>
            </geometry>
          </collision>
          <visual name='visual'>
            <pose frame=''>0 0 -0.0035 0 -0 0</pose>
            <geometry>
              <cylinder>
                <radius>0.023</radius>
                <length>0.007</length>
              </cylinder>
            </geometry>
            <material>
              <script>
                <uri>file://media/materials/scripts/gazebo.material</uri>
                <name>Gazebo/DarkGrey</name>
              </script>
            </material>
          </visual>
          <pose frame=''>0 0 0 0 -0 0</pose>
        </link>
        <joint name='RoFICoM::extendJoint' type='prismatic'>
          <parent>RoFICoM::outer</parent>
          <child>RoFICoM::inner</child>
          <axis>
            <xyz>0 0 1</xyz>
            <limit>
              <lower>0</lower>
              <upper>0.007</upper>
              <effort>50</effort>
              <velocity>0.025</velocity>
            </limit>
            <initial_position>0</initial_position>
            <dynamics>
              <friction>0</friction>
              <spring_reference>0</spring_reference>
              <spring_stiffness>0</spring_stiffness>
            </dynamics>
            <use_parent_model_frame>1</use_parent_model_frame>
          </axis>
        </joint>
        <plugin name='roficom' filename='libroficomPlugin.so'>
          <joint>RoFICoM::extendJoint</joint>
          <extend>1</extend>
        </plugin>
      </model>
      <model name='connectorBplusX'>
        <pose frame=''>-0.043 0.05 0 -1.5708 0 1.5708</pose>
        <self_collide>0</self_collide>
        <link name='RoFICoM::outer'>
          <inertial>
            <pose frame=''>0 0 -0.0085 0 -0 0</pose>
            <mass>0.01</mass>
            <inertia>
              <ixx>1.77583e-06</ixx>
              <iyy>1.77583e-06</iyy>
              <izz>3.125e-06</izz>
              <ixy>0</ixy>
              <ixz>0</ixz>
              <iyz>0</iyz>
            </inertia>
          </inertial>
          <collision name='outer-collision'>
            <pose frame=''>0 0 -0.0085 0 -0 0</pose>
            <geometry>
              <cylinder>
                <radius>0.025</radius>
                <length>0.017</length>
              </cylinder>
            </geometry>
          </collision>
          <visual name='visual'>
            <pose frame=''>0 0 -0.0085 0 -0 0</pose>
            <geometry>
              <cylinder>
                <radius>0.025</radius>
                <length>0.017</length>
              </cylinder>
            </geometry>
            <material>
              <script>
                <uri>file://media/materials/scripts/gazebo.material</uri>
                <name>Gazebo/DarkGrey</name>
              </script>
            </material>
          </visual>
          <pose frame=''>0 0 0 0 -0 0</pose>
        </link>
        <link name='RoFICoM::inner'>
          <inertial>
            <pose frame=''>0 0 -0.0035 0 -0 0</pose>
            <mass>0.01</mass>
            <inertia>
              <ixx>1.3633e-06</ixx>
              <iyy>1.3633e-06</iyy>
              <izz>2.645e-06</izz>
              <ixy>0</ixy>
              <ixz>0</ixz>
              <iyz>0</iyz>
            </inertia>
          </inertial>
          <collision name='inner-collision'>
            <pose frame=''>0 0 -0.0035 0 -0 0</pose>
            <geometry>
              <cylinder>
                <radius>0.023</radius>
                <length>0.007</length>
              </cylinder>
            </geometry>
          </collision>
          <visual name='visual'>
            <pose frame=''>0 0 -0.0035 0 -0 0</pose>
            <geometry>
              <cylinder>
                <radius>0.023</radius>
                <length>0.007</length>
              </cylinder>
            </geometry>
            <material>
              <script>
                <uri>file://media/materials/scripts/gazebo.material</uri>
                <name>Gazebo/DarkGrey</name>
              </script>
            </material>
          </visual>
          <pose frame=''>0 0 0 0 -0 0</pose>
        </link>
        <joint name='RoFICoM::extendJoint' type='prismatic'>
          <parent>RoFICoM::outer</parent>
          <child>RoFICoM::inner</child>
          <axis>
            <xyz>0 0 1</xyz>
            <limit>
              <lower>0</lower>
              <upper>0.007</upper>
              <effort>50</effort>
              <velocity>0.025</velocity>
            </limit>
            <initial_position>0</initial_position>
            <dynamics>
              <friction>0</friction>
              <spring_reference>0</spring_reference>
              <spring_stiffness>0</spring_stiffness>
            </dynamics>
            <use_parent_model_frame>1</use_parent_model_frame>
          </axis>
        </joint>
        <plugin name='roficom' filename='libroficomPlugin.so'>
          <joint>RoFICoM::extendJoint</joint>
          <extend>0</extend>
        </plugin>
      </model>
      <model name='connectorBminusX'>
        <pose frame=''>0.043 0.05 0 -1.5708 -0 -1.5708</pose>
        <self_collide>0</self_collide>
        <link name='RoFICoM::outer'>
          <inertial>
            <pose frame=''>0 0 -0.0085 0 -0 0</pose>
            <mass>0.01</mass>
            <inertia>
              <ixx>1.77583e-06</ixx>
              <iyy>1.77583e-06</iyy>
              <izz>3.125e-06</izz>
              <ixy>0</ixy>
              <ixz>0</ixz>
              <iyz>0</iyz>
            </inertia>
          </inertial>
          <collision name='outer-collision'>
            <pose frame=''>0 0 -0.0085 0 -0 0</pose>
            <geometry>
              <cylinder>
                <radius>0.025</radius>
                <length>0.017</length>
              </cylinder>
            </geometry>
          </collision>
          <visual name='visual'>
            <pose frame=''>0 0 -0.0085 0 -0 0</pose>
            <geometry>
              <cylinder>
                <radius>0.025</radius>
                <length>0.017</length>
              </cylinder>
            </geometry>
            <material>
              <script>
                <uri>file://media/materials/scripts/gazebo.material</uri>
                <name>Gazebo/DarkGrey</name>
              </script>
            </material>
          </visual>
          <pose frame=''>0 0 0 0 -0 0</pose>
        </link>
        <link name='RoFICoM::inner'>
          <inertial>
            <pose frame=''>0 0 -0.0035 0 -0 0</pose>
            <mass>0.01</mass>
            <inertia>
              <ixx>1.3633e-06</ixx>
              <iyy>1.3633e-06</iyy>
              <izz>2.645e-06</izz>
              <ixy>0</ixy>
              <ixz>0</ixz>
              <iyz>0</iyz>
            </inertia>
          </inertial>
          <collision name='inner-collision'>
            <pose frame=''>0 0 -0.0035 0 -0 0</pose>
            <geometry>
              <cylinder>
                <radius>0.023</radius>
                <length>0.007</length>
              </cylinder>
            </geometry>
          </collision>
          <visual name='visual'>
            <pose frame=''>0 0 -0.0035 0 -0 0</pose>
            <geometry>
              <cylinder>
                <radius>0.023</radius>
                <length>0.007</length>
              </cylinder>
            </geometry>
            <material>
              <script>
                <uri>file://media/materials/scripts/gazebo.material</uri>
                <name>Gazebo/DarkGrey</name>
              </script>
            </material>
          </visual>
          <pose frame=''>0 0 0 0 -0 0</pose>
        </link>
        <joint name='RoFICoM::extendJoint' type='prismatic'>
          <parent>RoFICoM::outer</parent>
          <child>RoFICoM::inner</child>
          <axis>
            <xyz>0 0 1</xyz>
            <limit>
              <lower>0</lower>
              <upper>0.007</upper>
              <effort>50</effort>
              <velocity>0.025</velocity>
            </limit>
            <initial_position>0</initial_position>
            <dynamics>
              <friction>0</friction>
              <spring_reference>0</spring_reference>
              <spring_stiffness>0</spring_stiffness>
            </dynamics>
            <use_parent_model_frame>1</use_parent_model_frame>
          </axis>
        </joint>
        <plugin name='roficom' filename='libroficomPlugin.so'>
          <joint>RoFICoM::extendJoint</joint>
          <extend>0</extend>
        </plugin>
      </model>
      <model name='connectorBminusZ'>
        <pose frame=''>0 0.093 0 1.5708 -0 -3.14159</pose>
        <self_collide>0</self_collide>
        <link name='RoFICoM::outer'>
          <inertial>
            <pose frame=''>0 0 -0.0085 0 -0 0</pose>
            <mass>0.01</mass>
            <inertia>
              <ixx>1.77583e-06</ixx>
              <iyy>1.77583e-06</iyy>
              <izz>3.125e-06</izz>
              <ixy>0</ixy>
              <ixz>0</ixz>
              <iyz>0</iyz>
            </inertia>
          </inertial>
          <collision name='outer-collision'>
            <pose frame=''>0 0 -0.0085 0 -0 0</pose>
            <geometry>
              <cylinder>
                <radius>0.025</radius>
                <length>0.017</length>
              </cylinder>
            </geometry>
          </collision>
          <visual name='visual'>
            <pose frame=''>0 0 -0.0085 0 -0 0</pose>
            <geometry>
              <cylinder>
                <radius>0.025</radius>
                <length>0.017</length>
              </cylinder>
            </geometry>
            <material>
              <script>
                <uri>file://media/materials/scripts/gazebo.material</uri>
                <name>Gazebo/DarkGrey</name>
              </script>
            </material>
          </visual>
          <pose frame=''>0 0 0 0 -0 0</pose>
        </link>
        <link name='RoFICoM::inner'>
          <inertial>
            <pose frame=''>0 0 -0.0035 0 -0 0</pose>
            <mass>0.01</mass>
            <inertia>
              <ixx>1.3633e-06</ixx>
              <iyy>1.3633e-06</iyy>
              <izz>2.645e-06</izz>
              <ixy>0</ixy>
              <ixz>0</ixz>
              <iyz>0</iyz>
            </inertia>
          </inertial>
          <collision name='inner-collision'>
            <pose frame=''>0 0 -0.0035 0 -0 0</pose>
            <geometry>
              <cylinder>
                <radius>0.023</radius>
                <length>0.007</length>
              </cylinder>
            </geometry>
          </collision>
          <visual name='visual'>
            <pose frame=''>0 0 -0.0035 0 -0 0</pose>
            <geometry>
              <cylinder>
                <radius>0.023</radius>
                <length>0.007</length>
              </cylinder>
            </geometry>
            <material>
              <script>
                <uri>file://media/materials/scripts/gazebo.material</uri>
                <name>Gazebo/DarkGrey</name>
              </script>
            </material>
          </visual>
          <pose frame=''>0 0 0 0 -0 0</pose>
        </link>
        <joint name='RoFICoM::extendJoint' type='prismatic'>
          <parent>RoFICoM::outer</parent>
          <child>RoFICoM::inner</child>
          <axis>
            <xyz>0 0 1</xyz>
            <limit>
              <lower>0</lower>
              <upper>0.007</upper>
              <effort>50</effort>
              <velocity>0.025</velocity>
            </limit>
            <initial_position>0</initial_position>
            <dynamics>
              <friction>0</friction>
              <spring_reference>0</spring_reference>
              <spring_stiffness>0</spring_stiffness>
            </dynamics>
            <use_parent_model_frame>1</use_parent_model_frame>
          </axis>
        </joint>
        <plugin name='roficom' filename='libroficomPlugin.so'>
          <joint>RoFICoM::extendJoint</joint>
          <extend>0</extend>
        </plugin>
      </model>
      <joint name='bodyRev' type='revolute'>
        <child>bodyB</child>
        <parent>bodyA</parent>
        <axis>
          <xyz>0 0.01 0</xyz>
          <limit>
            <velocity>6.545</velocity>
            <effort>1.2</effort>
            <lower>-1e+16</lower>
            <upper>1e+16</upper>
          </limit>
          <dynamics>
            <friction>0</friction>
            <spring_reference>0</spring_reference>
            <spring_stiffness>0</spring_stiffness>
          </dynamics>
          <use_parent_model_frame>1</use_parent_model_frame>
        </axis>
      </joint>
      <joint name='shoeARev' type='revolute'>
        <child>shoeA</child>
        <parent>bodyA</parent>
        <axis>
          <xyz>-0.01 0 0</xyz>
          <limit>
            <lower>-1.5708</lower>
            <upper>1.5708</upper>
            <velocity>6.545</velocity>
            <effort>1.2</effort>
          </limit>
          <dynamics>
            <friction>0</friction>
            <spring_reference>0</spring_reference>
            <spring_stiffness>0</spring_stiffness>
          </dynamics>
          <use_parent_model_frame>1</use_parent_model_frame>
        </axis>
      </joint>
      <joint name='shoeBRev' type='revolute'>
        <child>shoeB</child>
        <parent>bodyB</parent>
        <axis>
          <xyz>0.01 0 0</xyz>
          <limit>
            <lower>-1.5708</lower>
            <upper>1.5708</upper>
            <velocity>6.545</velocity>
            <effort>1.2</effort>
          </limit>
          <dynamics>
            <friction>0</friction>
            <spring_reference>0</spring_reference>
            <spring_stiffness>0</spring_stiffness>
          </dynamics>
          <use_parent_model_frame>1</use_parent_model_frame>
        </axis>
      </joint>
      <joint name='connectorAplusX' type='fixed'>
        <child>connectorAplusX::RoFICoM::outer</child>
        <parent>shoeA</parent>
      </joint>
      <joint name='connectorAminusX' type='fixed'>
        <child>connectorAminusX::RoFICoM::outer</child>
        <parent>shoeA</parent>
      </joint>
      <joint name='connectorAminusZ' type='fixed'>
        <child>connectorAminusZ::RoFICoM::outer</child>
        <parent>shoeA</parent>
      </joint>
      <joint name='connectorBplusX' type='fixed'>
        <child>connectorBplusX::RoFICoM::outer</child>
        <parent>shoeB</parent>
      </joint>
      <joint name='connectorBminusX' type='fixed'>
        <child>connectorBminusX::RoFICoM::outer</child>
        <parent>shoeB</parent>
      </joint>
      <joint name='connectorBminusZ' type='fixed'>
        <child>connectorBminusZ::RoFICoM::outer</child>
        <parent>shoeB</parent>
      </joint>
      <plugin name='rofiModule' filename='librofiModulePlugin.so'>
        <controller>
          <joint>shoeARev</joint>
          <joint>shoeBRev</joint>
          <joint>bodyRev</joint>
          <velocity>
            <pid_gains>0.05 10 0</pid_gains>
          </velocity>
          <position>
            <pid_gains>5 15 1</pid_gains>
          </position>
        </controller>
      </plugin>
    </model>
    <model name='rofi_1'>
      <link name='bodyA'>
        <self_collide>1</self_collide>
        <inertial>
          <pose frame=''>0 -0.029663 0 0 -0 0</pose>
          <mass>0.201058</mass>
          <inertia>
            <ixx>0.00016</ixx>
            <ixy>0</ixy>
            <ixz>0</ixz>
            <iyy>0.00013</iyy>
            <iyz>0</iyz>
            <izz>0.000158</izz>
          </inertia>
        </inertial>
        <visual name='visual-bodyA'>
          <pose frame=''>0 0 0 0 -0 0</pose>
          <geometry>
            <mesh>
              <uri>model://universalModule/meshes/model.obj</uri>
              <scale>0.001 0.001 0.001</scale>
              <submesh>
                <name>bodyA</name>
              </submesh>
            </mesh>
          </geometry>
          <material>
            <lighting>1</lighting>
            <script>
              <uri>file://media/materials/scripts/gazebo.material</uri>
              <name>Gazebo/DarkGrey</name>
            </script>
            <shader type='pixel'>
              <normal_map>__default__</normal_map>
            </shader>
          </material>
        </visual>
        <collision name='collision-bodyA'>
          <pose frame=''>0 0 0 0 -0 0</pose>
          <geometry>
            <mesh>
              <uri>model://universalModule/meshes/model.obj</uri>
              <scale>0.001 0.001 0.001</scale>
              <submesh>
                <name>bodyA</name>
              </submesh>
            </mesh>
          </geometry>
        </collision>
      </link>
      <link name='bodyB'>
        <self_collide>1</self_collide>
        <inertial>
          <pose frame=''>0 0.029663 0 0 -0 0</pose>
          <mass>0.201058</mass>
          <inertia>
            <ixx>0.00016</ixx>
            <ixy>0</ixy>
            <ixz>0</ixz>
            <iyy>0.00013</iyy>
            <iyz>0</iyz>
            <izz>0.000158</izz>
          </inertia>
        </inertial>
        <visual name='visual-bodyB'>
          <pose frame=''>0 0 0 0 -0 0</pose>
          <geometry>
            <mesh>
              <uri>model://universalModule/meshes/model.obj</uri>
              <scale>0.001 0.001 0.001</scale>
              <submesh>
                <name>bodyB</name>
              </submesh>
            </mesh>
          </geometry>
          <material>
            <lighting>1</lighting>
            <script>
              <uri>file://media/materials/scripts/gazebo.material</uri>
              <name>Gazebo/DarkGrey</name>
            </script>
            <shader type='pixel'>
              <normal_map>__default__</normal_map>
            </shader>
          </material>
        </visual>
        <collision name='collision-bodyB'>
          <pose frame=''>0 0 0 0 -0 0</pose>
          <geometry>
            <mesh>
              <uri>model://universalModule/meshes/model.obj</uri>
              <scale>0.001 0.001 0.001</scale>
              <submesh>
                <name>bodyB</name>
              </submesh>
            </mesh>
          </geometry>
        </collision>
      </link>
      <link name='shoeA'>
        <self_collide>0</self_collide>
        <pose frame=''>-0.0265 -0.05 0 0 -0 0</pose>
        <inertial>
          <pose frame=''>0.0265 -0.012973 0 0 -0 0</pose>
          <mass>0.089474</mass>
          <inertia>
            <ixx>5.9e-05</ixx>
            <ixy>0</ixy>
            <ixz>0</ixz>
            <iyy>0.000103</iyy>
            <iyz>0</iyz>
            <izz>0.000117</izz>
          </inertia>
        </inertial>
        <collision name='shoeA-collision'>
          <pose frame=''>0.0265 0.05 -0 0 -0 0</pose>
          <geometry>
            <mesh>
              <uri>model://universalModule/meshes/model.obj</uri>
              <scale>0.001 0.001 0.001</scale>
              <submesh>
                <name>shoeA</name>
              </submesh>
            </mesh>
          </geometry>
        </collision>
        <visual name='shoeA-visual'>
          <pose frame=''>0.0265 0.05 -0 0 -0 0</pose>
          <geometry>
            <mesh>
              <uri>model://universalModule/meshes/model.obj</uri>
              <scale>0.001 0.001 0.001</scale>
              <submesh>
                <name>shoeA</name>
              </submesh>
            </mesh>
          </geometry>
          <material>
            <lighting>1</lighting>
            <script>
              <uri>file://media/materials/scripts/gazebo.material</uri>
              <name>Gazebo/Yellow</name>
            </script>
            <shader type='pixel'>
              <normal_map>__default__</normal_map>
            </shader>
          </material>
        </visual>
      </link>
      <link name='shoeB'>
        <self_collide>0</self_collide>
        <pose frame=''>-0.0265 0.05 0.0015 0 -0 0</pose>
        <inertial>
          <pose frame=''>0.0265 0.012973 0 0 -0 0</pose>
          <mass>0.089474</mass>
          <inertia>
            <ixx>5.9e-05</ixx>
            <ixy>0</ixy>
            <ixz>0</ixz>
            <iyy>0.000103</iyy>
            <iyz>0</iyz>
            <izz>0.000117</izz>
          </inertia>
        </inertial>
        <collision name='shoeB-collision'>
          <pose frame=''>0.0265 -0.05 -0.0015 0 -0 0</pose>
          <geometry>
            <mesh>
              <uri>model://universalModule/meshes/model.obj</uri>
              <scale>0.001 0.001 0.001</scale>
              <submesh>
                <name>shoeB</name>
              </submesh>
            </mesh>
          </geometry>
        </collision>
        <visual name='shoeB-visual'>
          <pose frame=''>0.0265 -0.05 -0.0015 0 -0 0</pose>
          <geometry>
            <mesh>
              <uri>model://universalModule/meshes/model.obj</uri>
              <scale>0.001 0.001 0.001</scale>
              <submesh>
                <name>shoeB</name>
              </submesh>
            </mesh>
          </geometry>
          <material>
            <lighting>1</lighting>
            <script>
              <uri>file://media/materials/scripts/gazebo.material</uri>
              <name>Gazebo/Yellow</name>
            </script>
            <shader type='pixel'>
              <normal_map>__default__</normal_map>
            </shader>
          </material>
        </visual>
      </link>
      <model name='connectorAplusX'>
        <pose frame=''>0.043 -0.05 0 -1.5708 -0 -1.5708</pose>
        <self_collide>0</self_collide>
        <link name='RoFICoM::outer'>
          <inertial>
            <pose frame=''>0 0 -0.0085 0 -0 0</pose>
            <mass>0.01</mass>
            <inertia>
              <ixx>1.77583e-06</ixx>
              <iyy>1.77583e-06</iyy>
              <izz>3.125e-06</izz>
              <ixy>0</ixy>
              <ixz>0</ixz>
              <iyz>0</iyz>
            </inertia>
          </inertial>
          <collision name='outer-collision'>
            <pose frame=''>0 0 -0.0085 0 -0 0</pose>
            <geometry>
              <cylinder>
                <radius>0.025</radius>
                <length>0.017</length>
              </cylinder>
            </geometry>
          </collision>
          <visual name='visual'>
            <pose frame=''>0 0 -0.0085 0 -0 0</pose>
            <geometry>
              <cylinder>
                <radius>0.025</radius>
                <length>0.017</length>
              </cylinder>
            </geometry>
            <material>
              <script>
                <uri>file://media/materials/scripts/gazebo.material</uri>
                <name>Gazebo/DarkGrey</name>
              </script>
            </material>
          </visual>
          <pose frame=''>0 0 0 0 -0 0</pose>
        </link>
        <link name='RoFICoM::inner'>
          <inertial>
            <pose frame=''>0 0 -0.0035 0 -0 0</pose>
            <mass>0.01</mass>
            <inertia>
              <ixx>1.3633e-06</ixx>
              <iyy>1.3633e-06</iyy>
              <izz>2.645e-06</izz>
              <ixy>0</ixy>
              <ixz>0</ixz>
              <iyz>0</iyz>
            </inertia>
          </inertial>
          <collision name='inner-collision'>
            <pose frame=''>0 0 -0.0035 0 -0 0</pose>
            <geometry>
              <cylinder>
                <radius>0.023</radius>
                <length>0.007</length>
              </cylinder>
            </geometry>
          </collision>
          <visual name='visual'>
            <pose frame=''>0 0 -0.0035 0 -0 0</pose>
            <geometry>
              <cylinder>
                <radius>0.023</radius>
                <length>0.007</length>
              </cylinder>
            </geometry>
            <material>
              <script>
                <uri>file://media/materials/scripts/gazebo.material</uri>
                <name>Gazebo/DarkGrey</name>
              </script>
            </material>
          </visual>
          <pose frame=''>0 0 0 0 -0 0</pose>
        </link>
        <joint name='RoFICoM::extendJoint' type='prismatic'>
          <parent>RoFICoM::outer</parent>
          <child>RoFICoM::inner</child>
          <axis>
            <xyz>0 0 1</xyz>
            <limit>
              <lower>0</lower>
              <upper>0.007</upper>
              <effort>50</effort>
              <velocity>0.025</velocity>
            </limit>
            <initial_position>0</initial_position>
            <dynamics>
              <friction>0</friction>
              <spring_reference>0</spring_reference>
              <spring_stiffness>0</spring_stiffness>
            </dynamics>
            <use_parent_model_frame>1</use_parent_model_frame>
          </axis>
        </joint>
        <plugin name='roficom' filename='libroficomPlugin.so'>
          <joint>RoFICoM::extendJoint</joint>
          <extend>0</extend>
        </plugin>
      </model>
      <model name='connectorAminusX'>
        <pose frame=''>-0.043 -0.05 0 -1.5708 0 1.5708</pose>
        <self_collide>0</self_collide>
        <link name='RoFICoM::outer'>
          <inertial>
            <pose frame=''>0 0 -0.0085 0 -0 0</pose>
            <mass>0.01</mass>
            <inertia>
              <ixx>1.77583e-06</ixx>
              <iyy>1.77583e-06</iyy>
              <izz>3.125e-06</izz>
              <ixy>0</ixy>
              <ixz>0</ixz>
              <iyz>0</iyz>
            </inertia>
          </inertial>
          <collision name='outer-collision'>
            <pose frame=''>0 0 -0.0085 0 -0 0</pose>
            <geometry>
              <cylinder>
                <radius>0.025</radius>
                <length>0.017</length>
              </cylinder>
            </geometry>
          </collision>
          <visual name='visual'>
            <pose frame=''>0 0 -0.0085 0 -0 0</pose>
            <geometry>
              <cylinder>
                <radius>0.025</radius>
                <length>0.017</length>
              </cylinder>
            </geometry>
            <material>
              <script>
                <uri>file://media/materials/scripts/gazebo.material</uri>
                <name>Gazebo/DarkGrey</name>
              </script>
            </material>
          </visual>
          <pose frame=''>0 0 0 0 -0 0</pose>
        </link>
        <link name='RoFICoM::inner'>
          <inertial>
            <pose frame=''>0 0 -0.0035 0 -0 0</pose>
            <mass>0.01</mass>
            <inertia>
              <ixx>1.3633e-06</ixx>
              <iyy>1.3633e-06</iyy>
              <izz>2.645e-06</izz>
              <ixy>0</ixy>
              <ixz>0</ixz>
              <iyz>0</iyz>
            </inertia>
          </inertial>
          <collision name='inner-collision'>
            <pose frame=''>0 0 -0.0035 0 -0 0</pose>
            <geometry>
              <cylinder>
                <radius>0.023</radius>
                <length>0.007</length>
              </cylinder>
            </geometry>
          </collision>
          <visual name='visual'>
            <pose frame=''>0 0 -0.0035 0 -0 0</pose>
            <geometry>
              <cylinder>
                <radius>0.023</radius>
                <length>0.007</length>
              </cylinder>
            </geometry>
            <material>
              <script>
                <uri>file://media/materials/scripts/gazebo.material</uri>
                <name>Gazebo/DarkGrey</name>
              </script>
            </material>
          </visual>
          <pose frame=''>0 0 0 0 -0 0</pose>
        </link>
        <joint name='RoFICoM::extendJoint' type='prismatic'>
          <parent>RoFICoM::outer</parent>
          <child>RoFICoM::inner</child>
          <axis>
            <xyz>0 0 1</xyz>
            <limit>
              <lower>0</lower>
              <upper>0.007</upper>
              <effort>50</effort>
              <velocity>0.025</velocity>
            </limit>
            <initial_position>0</initial_position>
            <dynamics>
              <friction>0</friction>
              <spring_reference>0</spring_reference>
              <spring_stiffness>0</spring_stiffness>
            </dynamics>
            <use_parent_model_frame>1</use_parent_model_frame>
          </axis>
        </joint>
        <plugin name='roficom' filename='libroficomPlugin.so'>
          <joint>RoFICoM::extendJoint</joint>
          <extend>0</extend>
        </plugin>
      </model>
      <model name='connectorAminusZ'>
        <pose frame=''>0 -0.093 0 1.5708 -0 0</pose>
        <self_collide>0</self_collide>
        <link name='RoFICoM::outer'>
          <inertial>
            <pose frame=''>0 0 -0.0085 0 -0 0</pose>
            <mass>0.01</mass>
            <inertia>
              <ixx>1.77583e-06</ixx>
              <iyy>1.77583e-06</iyy>
              <izz>3.125e-06</izz>
              <ixy>0</ixy>
              <ixz>0</ixz>
              <iyz>0</iyz>
            </inertia>
          </inertial>
          <collision name='outer-collision'>
            <pose frame=''>0 0 -0.0085 0 -0 0</pose>
            <geometry>
              <cylinder>
                <radius>0.025</radius>
                <length>0.017</length>
              </cylinder>
            </geometry>
          </collision>
          <visual name='visual'>
            <pose frame=''>0 0 -0.0085 0 -0 0</pose>
            <geometry>
              <cylinder>
                <radius>0.025</radius>
                <length>0.017</length>
              </cylinder>
            </geometry>
            <material>
              <script>
                <uri>file://media/materials/scripts/gazebo.material</uri>
                <name>Gazebo/DarkGrey</name>
              </script>
            </material>
          </visual>
          <pose frame=''>0 0 0 0 -0 0</pose>
        </link>
        <link name='RoFICoM::inner'>
          <inertial>
            <pose frame=''>0 0 -0.0035 0 -0 0</pose>
            <mass>0.01</mass>
            <inertia>
              <ixx>1.3633e-06</ixx>
              <iyy>1.3633e-06</iyy>
              <izz>2.645e-06</izz>
              <ixy>0</ixy>
              <ixz>0</ixz>
              <iyz>0</iyz>
            </inertia>
          </inertial>
          <collision name='inner-collision'>
            <pose frame=''>0 0 -0.0035 0 -0 0</pose>
            <geometry>
              <cylinder>
                <radius>0.023</radius>
                <length>0.007</length>
              </cylinder>
            </geometry>
          </collision>
          <visual name='visual'>
            <pose frame=''>0 0 -0.0035 0 -0 0</pose>
            <geometry>
              <cylinder>
                <radius>0.023</radius>
                <length>0.007</length>
              </cylinder>
            </geometry>
            <material>
              <script>
                <uri>file://media/materials/scripts/gazebo.material</uri>
                <name>Gazebo/DarkGrey</name>
              </script>
            </material>
          </visual>
          <pose frame=''>0 0 0 0 -0 0</pose>
        </link>
        <joint name='RoFICoM::extendJoint' type='prismatic'>
          <parent>RoFICoM::outer</parent>
          <child>RoFICoM::inner</child>
          <axis>
            <xyz>0 0 1</xyz>
            <limit>
              <lower>0</lower>
              <upper>0.007</upper>
              <effort>50</effort>
              <velocity>0.025</velocity>
            </limit>
            <initial_position>0</initial_position>
            <dynamics>
              <friction>0</friction>
              <spring_reference>0</spring_reference>
              <spring_stiffness>0</spring_stiffness>
            </dynamics>
            <use_parent_model_frame>1</use_parent_model_frame>
          </axis>
        </joint>
        <plugin name='roficom' filename='libroficomPlugin.so'>
          <joint>RoFICoM::extendJoint</joint>
          <extend>1</extend>
        </plugin>
      </model>
      <model name='connectorBplusX'>
        <pose frame=''>-0.043 0.05 0 -1.5708 0 1.5708</pose>
        <self_collide>0</self_collide>
        <link name='RoFICoM::outer'>
          <inertial>
            <pose frame=''>0 0 -0.0085 0 -0 0</pose>
            <mass>0.01</mass>
            <inertia>
              <ixx>1.77583e-06</ixx>
              <iyy>1.77583e-06</iyy>
              <izz>3.125e-06</izz>
              <ixy>0</ixy>
              <ixz>0</ixz>
              <iyz>0</iyz>
            </inertia>
          </inertial>
          <collision name='outer-collision'>
            <pose frame=''>0 0 -0.0085 0 -0 0</pose>
            <geometry>
              <cylinder>
                <radius>0.025</radius>
                <length>0.017</length>
              </cylinder>
            </geometry>
          </collision>
          <visual name='visual'>
            <pose frame=''>0 0 -0.0085 0 -0 0</pose>
            <geometry>
              <cylinder>
                <radius>0.025</radius>
                <length>0.017</length>
              </cylinder>
            </geometry>
            <material>
              <script>
                <uri>file://media/materials/scripts/gazebo.material</uri>
                <name>Gazebo/DarkGrey</name>
              </script>
            </material>
          </visual>
          <pose frame=''>0 0 0 0 -0 0</pose>
        </link>
        <link name='RoFICoM::inner'>
          <inertial>
            <pose frame=''>0 0 -0.0035 0 -0 0</pose>
            <mass>0.01</mass>
            <inertia>
              <ixx>1.3633e-06</ixx>
              <iyy>1.3633e-06</iyy>
              <izz>2.645e-06</izz>
              <ixy>0</ixy>
              <ixz>0</ixz>
              <iyz>0</iyz>
            </inertia>
          </inertial>
          <collision name='inner-collision'>
            <pose frame=''>0 0 -0.0035 0 -0 0</pose>
            <geometry>
              <cylinder>
                <radius>0.023</radius>
                <length>0.007</length>
              </cylinder>
            </geometry>
          </collision>
          <visual name='visual'>
            <pose frame=''>0 0 -0.0035 0 -0 0</pose>
            <geometry>
              <cylinder>
                <radius>0.023</radius>
                <length>0.007</length>
              </cylinder>
            </geometry>
            <material>
              <script>
                <uri>file://media/materials/scripts/gazebo.material</uri>
                <name>Gazebo/DarkGrey</name>
              </script>
            </material>
          </visual>
          <pose frame=''>0 0 0 0 -0 0</pose>
        </link>
        <joint name='RoFICoM::extendJoint' type='prismatic'>
          <parent>RoFICoM::outer</parent>
          <child>RoFICoM::inner</child>
          <axis>
            <xyz>0 0 1</xyz>
            <limit>
              <lower>0</lower>
              <upper>0.007</upper>
              <effort>50</effort>
              <velocity>0.025</velocity>
            </limit>
            <initial_position>0</initial_position>
            <dynamics>
              <friction>0</friction>
              <spring_reference>0</spring_reference>
              <spring_stiffness>0</spring_stiffness>
            </dynamics>
            <use_parent_model_frame>1</use_parent_model_frame>
          </axis>
        </joint>
        <plugin name='roficom' filename='libroficomPlugin.so'>
          <joint>RoFICoM::extendJoint</joint>
          <extend>0</extend>
        </plugin>
      </model>
      <model name='connectorBminusX'>
        <pose frame=''>0.043 0.05 0 -1.5708 -0 -1.5708</pose>
        <self_collide>0</self_collide>
        <link name='RoFICoM::outer'>
          <inertial>
            <pose frame=''>0 0 -0.0085 0 -0 0</pose>
            <mass>0.01</mass>
            <inertia>
              <ixx>1.77583e-06</ixx>
              <iyy>1.77583e-06</iyy>
              <izz>3.125e-06</izz>
              <ixy>0</ixy>
              <ixz>0</ixz>
              <iyz>0</iyz>
            </inertia>
          </inertial>
          <collision name='outer-collision'>
            <pose frame=''>0 0 -0.0085 0 -0 0</pose>
            <geometry>
              <cylinder>
                <radius>0.025</radius>
                <length>0.017</length>
              </cylinder>
            </geometry>
          </collision>
          <visual name='visual'>
            <pose frame=''>0 0 -0.0085 0 -0 0</pose>
            <geometry>
              <cylinder>
                <radius>0.025</radius>
                <length>0.017</length>
              </cylinder>
            </geometry>
            <material>
              <script>
                <uri>file://media/materials/scripts/gazebo.material</uri>
                <name>Gazebo/DarkGrey</name>
              </script>
            </material>
          </visual>
          <pose frame=''>0 0 0 0 -0 0</pose>
        </link>
        <link name='RoFICoM::inner'>
          <inertial>
            <pose frame=''>0 0 -0.0035 0 -0 0</pose>
            <mass>0.01</mass>
            <inertia>
              <ixx>1.3633e-06</ixx>
              <iyy>1.3633e-06</iyy>
              <izz>2.645e-06</izz>
              <ixy>0</ixy>
              <ixz>0</ixz>
              <iyz>0</iyz>
            </inertia>
          </inertial>
          <collision name='inner-collision'>
            <pose frame=''>0 0 -0.0035 0 -0 0</pose>
            <geometry>
              <cylinder>
                <radius>0.023</radius>
                <length>0.007</length>
              </cylinder>
            </geometry>
          </collision>
          <visual name='visual'>
            <pose frame=''>0 0 -0.0035 0 -0 0</pose>
            <geometry>
              <cylinder>
                <radius>0.023</radius>
                <length>0.007</length>
              </cylinder>
            </geometry>
            <material>
              <script>
                <uri>file://media/materials/scripts/gazebo.material</uri>
                <name>Gazebo/DarkGrey</name>
              </script>
            </material>
          </visual>
          <pose frame=''>0 0 0 0 -0 0</pose>
        </link>
        <joint name='RoFICoM::extendJoint' type='prismatic'>
          <parent>RoFICoM::outer</parent>
          <child>RoFICoM::inner</child>
          <axis>
            <xyz>0 0 1</xyz>
            <limit>
              <lower>0</lower>
              <upper>0.007</upper>
              <effort>50</effort>
              <velocity>0.025</velocity>
            </limit>
            <initial_position>0</initial_position>
            <dynamics>
              <friction>0</friction>
              <spring_reference>0</spring_reference>
              <spring_stiffness>0</spring_stiffness>
            </dynamics>
            <use_parent_model_frame>1</use_parent_model_frame>
          </axis>
        </joint>
        <plugin name='roficom' filename='libroficomPlugin.so'>
          <joint>RoFICoM::extendJoint</joint>
          <extend>0</extend>
        </plugin>
      </model>
      <model name='connectorBminusZ'>
        <pose frame=''>0 0.093 0 1.5708 -0 -3.14159</pose>
        <self_collide>0</self_collide>
        <link name='RoFICoM::outer'>
          <inertial>
            <pose frame=''>0 0 -0.0085 0 -0 0</pose>
            <mass>0.01</mass>
            <inertia>
              <ixx>1.77583e-06</ixx>
              <iyy>1.77583e-06</iyy>
              <izz>3.125e-06</izz>
              <ixy>0</ixy>
              <ixz>0</ixz>
              <iyz>0</iyz>
            </inertia>
          </inertial>
          <collision name='outer-collision'>
            <pose frame=''>0 0 -0.0085 0 -0 0</pose>
            <geometry>
              <cylinder>
                <radius>0.025</radius>
                <length>0.017</length>
              </cylinder>
            </geometry>
          </collision>
          <visual name='visual'>
            <pose frame=''>0 0 -0.0085 0 -0 0</pose>
            <geometry>
              <cylinder>
                <radius>0.025</radius>
                <length>0.017</length>
              </cylinder>
            </geometry>
            <material>
              <script>
                <uri>file://media/materials/scripts/gazebo.material</uri>
                <name>Gazebo/DarkGrey</name>
              </script>
            </material>
          </visual>
          <pose frame=''>0 0 0 0 -0 0</pose>
        </link>
        <link name='RoFICoM::inner'>
          <inertial>
            <pose frame=''>0 0 -0.0035 0 -0 0</pose>
            <mass>0.01</mass>
            <inertia>
              <ixx>1.3633e-06</ixx>
              <iyy>1.3633e-06</iyy>
              <izz>2.645e-06</izz>
              <ixy>0</ixy>
              <ixz>0</ixz>
              <iyz>0</iyz>
            </inertia>
          </inertial>
          <collision name='inner-collision'>
            <pose frame=''>0 0 -0.0035 0 -0 0</pose>
            <geometry>
              <cylinder>
                <radius>0.023</radius>
                <length>0.007</length>
              </cylinder>
            </geometry>
          </collision>
          <visual name='visual'>
            <pose frame=''>0 0 -0.0035 0 -0 0</pose>
            <geometry>
              <cylinder>
                <radius>0.023</radius>
                <length>0.007</length>
              </cylinder>
            </geometry>
            <material>
              <script>
                <uri>file://media/materials/scripts/gazebo.material</uri>
                <name>Gazebo/DarkGrey</name>
              </script>
            </material>
          </visual>
          <pose frame=''>0 0 0 0 -0 0</pose>
        </link>
        <joint name='RoFICoM::extendJoint' type='prismatic'>
          <parent>RoFICoM::outer</parent>
          <child>RoFICoM::inner</child>
          <axis>
            <xyz>0 0 1</xyz>
            <limit>
              <lower>0</lower>
              <upper>0.007</upper>
              <effort>50</effort>
              <velocity>0.025</velocity>
            </limit>
            <initial_position>0</initial_position>
            <dynamics>
              <friction>0</friction>
              <spring_reference>0</spring_reference>
              <spring_stiffness>0</spring_stiffness>
            </dynamics>
            <use_parent_model_frame>1</use_parent_model_frame>
          </axis>
        </joint>
        <plugin name='roficom' filename='libroficomPlugin.so'>
          <joint>RoFICoM::extendJoint</joint>
          <extend>0</extend>
        </plugin>
      </model>
      <joint name='bodyRev' type='revolute'>
        <child>bodyB</child>
        <parent>bodyA</parent>
        <axis>
          <xyz>0 0.01 0</xyz>
          <limit>
            <velocity>6.545</velocity>
            <effort>1.2</effort>
            <lower>-1e+16</lower>
            <upper>1e+16</upper>
          </limit>
          <dynamics>
            <friction>0</friction>
            <spring_reference>0</spring_reference>
            <spring_stiffness>0</spring_stiffness>
          </dynamics>
          <use_parent_model_frame>1</use_parent_model_frame>
        </axis>
      </joint>
      <joint name='shoeARev' type='revolute'>
        <child>shoeA</child>
        <parent>bodyA</parent>
        <axis>
          <xyz>-0.01 0 0</xyz>
          <limit>
            <lower>-1.5708</lower>
            <upper>1.5708</upper>
            <velocity>6.545</velocity>
            <effort>1.2</effort>
          </limit>
          <dynamics>
            <friction>0</friction>
            <spring_reference>0</spring_reference>
            <spring_stiffness>0</spring_stiffness>
          </dynamics>
          <use_parent_model_frame>1</use_parent_model_frame>
        </axis>
      </joint>
      <joint name='shoeBRev' type='revolute'>
        <child>shoeB</child>
        <parent>bodyB</parent>
        <axis>
          <xyz>0.01 0 0</xyz>
          <limit>
            <lower>-1.5708</lower>
            <upper>1.5708</upper>
            <velocity>6.545</velocity>
            <effort>1.2</effort>
          </limit>
          <dynamics>
            <friction>0</friction>
            <spring_reference>0</spring_reference>
            <spring_stiffness>0</spring_stiffness>
          </dynamics>
          <use_parent_model_frame>1</use_parent_model_frame>
        </axis>
      </joint>
      <joint name='connectorAplusX' type='fixed'>
        <child>connectorAplusX::RoFICoM::outer</child>
        <parent>shoeA</parent>
      </joint>
      <joint name='connectorAminusX' type='fixed'>
        <child>connectorAminusX::RoFICoM::outer</child>
        <parent>shoeA</parent>
      </joint>
      <joint name='connectorAminusZ' type='fixed'>
        <child>connectorAminusZ::RoFICoM::outer</child>
        <parent>shoeA</parent>
      </joint>
      <joint name='connectorBplusX' type='fixed'>
        <child>connectorBplusX::RoFICoM::outer</child>
        <parent>shoeB</parent>
      </joint>
      <joint name='connectorBminusX' type='fixed'>
        <child>connectorBminusX::RoFICoM::outer</child>
        <parent>shoeB</parent>
      </joint>
      <joint name='connectorBminusZ' type='fixed'>
        <child>connectorBminusZ::RoFICoM::outer</child>
        <parent>shoeB</parent>
      </joint>
      <plugin name='rofiModule' filename='librofiModulePlugin.so'>
        <controller>
          <joint>shoeARev</joint>
          <joint>shoeBRev</joint>
          <joint>bodyRev</joint>
          <velocity>
            <pid_gains>0.05 10 0</pid_gains>
          </velocity>
          <position>
            <pid_gains>5 15 1</pid_gains>
          </position>
        </controller>
      </plugin>
    </model>
  </world>
</sdf>
